Workbook

Sheet Pricing and operating assumptio
A1: Pricing and operating assumptions
A2: Wincheck | 12-month plan · Main Scenario
A4: Variable / dimension | B4: Value
A5: Team monthly price | B5: =199 -> 199
A6: Included fixes per team | B6: =10 -> 10
A7: Extra fix price | B7: =29 -> 29
A8: Pay per fix price | B8: =49 -> 49
A9: Cost per successful fix | B9: =1.5 -> 1.5
A10: Target gross margin | B10: =0.7 -> 0.7
A11: Monthly hosting | B11: =50 -> 50
A12: Monthly tools | B12: =100 -> 100
A13: Founder monthly pay | B13: =4000 -> 4000
A14: Founder pay start month | B14: =7 -> 7
A15: Contract engineer monthly cost | B15: =6000 -> 6000
A16: Earliest hire month | B16: =10 -> 10
A17: Free fixes per project | B17: =1 -> 1

Sheet Monthly operating and hiring fo
A1: Monthly operating and hiring forecast
A2: Wincheck | 12-month plan · Main Scenario
A4: Variable / dimension | B4: 2026-10 | C4: 2026-11 | D4: 2026-12 | E4: 2027-01 | F4: 2027-02 | G4: 2027-03 | H4: 2027-04 | I4: 2027-05 | J4: 2027-06 | K4: 2027-07 | L4: 2027-08 | M4: 2027-09
A5: Paying teams | B5: =0 -> 0 | C5: =1 -> 1 | D5: =2 -> 2 | E5: =3 -> 3 | F5: =4 -> 4 | G5: =5 -> 5 | H5: =8 -> 8 | I5: =11 -> 11 | J5: =15 -> 15 | K5: =20 -> 20 | L5: =25 -> 25 | M5: =30 -> 30
A6: Free projects | B6: =3 -> 3 | C6: =6 -> 6 | D6: =10 -> 10 | E6: =10 -> 10 | F6: =10 -> 10 | G6: =10 -> 10 | H6: =10 -> 10 | I6: =10 -> 10 | J6: =10 -> 10 | K6: =10 -> 10 | ... M6: =10 -> 10
A7: Extra fixes per team | B7: =0 -> 0 | C7: =0 -> 0 | D7: =0 -> 0 | E7: =0 -> 0 | F7: =0 -> 0 | G7: =0 -> 0 | H7: =0 -> 0 | I7: =0 -> 0 | ... M7: =0 -> 0
A8: Paid standalone fixes | B8: =0 -> 0 | C8: =0 -> 0 | D8: =0 -> 0 | E8: =0 -> 0 | F8: =0 -> 0 | G8: =0 -> 0 | H8: =0 -> 0 | I8: =0 -> 0 | ... M8: =0 -> 0
A9: Plan month | B9: =DATEDIF(DATE(2026,10,1),DATE(2026,10,1),"M")+1 -> 1 | C9: =DATEDIF(DATE(2026,10,1),DATE(2026,11,1),"M")+1 -> 2 | D9: =DATEDIF(DATE(2026,10,1),DATE(2026,12,1),"M")+1 -> 3 | E9: =DATEDIF(DATE(2026,10,1),DATE(2027,1,1),"M")+1 -> 4 | F9: =DATEDIF(DATE(2026,10,1),DATE(2027,2,1),"M")+1 -> 5 | G9: =DATEDIF(DATE(2026,10,1),DATE(2027,3,1),"M")+1 -> 6 | H9: =DATEDIF(DATE(2026,10,1),DATE(2027,4,1),"M")+1 -> 7 | I9: =DATEDIF(DATE(2026,10,1),DATE(2027,5,1),"M")+1 -> 8 | J9: =DATEDIF(DATE(2026,10,1),DATE(2027,6,1),"M")+1 -> 9 | K9: =DATEDIF(DATE(2026,10,1),DATE(2027,7,1),"M")+1 -> 10 | L9: =DATEDIF(DATE(2026,10,1),DATE(2027,8,1),"M")+1 -> 11 | M9: =DATEDIF(DATE(2026,10,1),DATE(2027,9,1),"M")+1 -> 12
A10: Team successful fixes | B10: ='Monthly operating and hiring fo'!B5*'Pricing and operating assumptio'!B6 -> 0 | C10: ='Monthly operating and hiring fo'!C5*'Pricing and operating assumptio'!B6 -> 10 | D10: ='Monthly operating and hiring fo'!D5*'Pricing and operating assumptio'!B6 -> 20 | E10: ='Monthly operating and hiring fo'!E5*'Pricing and operating assumptio'!B6 -> 30 | F10: ='Monthly operating and hiring fo'!F5*'Pricing and operating assumptio'!B6 -> 40 | G10: ='Monthly operating and hiring fo'!G5*'Pricing and operating assumptio'!B6 -> 50 | H10: ='Monthly operating and hiring fo'!H5*'Pricing and operating assumptio'!B6 -> 80 | I10: ='Monthly operating and hiring fo'!I5*'Pricing and operating assumptio'!B6 -> 110 | J10: ='Monthly operating and hiring fo'!J5*'Pricing and operating assumptio'!B6 -> 150 | K10: ='Monthly operating and hiring fo'!K5*'Pricing and operating assumptio'!B6 -> 200 | L10: ='Monthly operating and hiring fo'!L5*'Pricing and operating assumptio'!B6 -> 250 | M10: ='Monthly operating and hiring fo'!M5*'Pricing and operating assumptio'!B6 -> 300
A11: Free successful fixes | B11: ='Monthly operating and hiring fo'!B6*'Pricing and operating assumptio'!B17 -> 3 | C11: ='Monthly operating and hiring fo'!C6*'Pricing and operating assumptio'!B17 -> 6 | D11: ='Monthly operating and hiring fo'!D6*'Pricing and operating assumptio'!B17 -> 10 | E11: ='Monthly operating and hiring fo'!E6*'Pricing and operating assumptio'!B17 -> 10 | F11: ='Monthly operating and hiring fo'!F6*'Pricing and operating assumptio'!B17 -> 10 | G11: ='Monthly operating and hiring fo'!G6*'Pricing and operating assumptio'!B17 -> 10 | H11: ='Monthly operating and hiring fo'!H6*'Pricing and operating assumptio'!B17 -> 10 | I11: ='Monthly operating and hiring fo'!I6*'Pricing and operating assumptio'!B17 -> 10 | J11: ='Monthly operating and hiring fo'!J6*'Pricing and operating assumptio'!B17 -> 10 | K11: ='Monthly operating and hiring fo'!K6*'Pricing and operating assumptio'!B17 -> 10 | L11: ='Monthly operating and hiring fo'!L6*'Pricing and operating assumptio'!B17 -> 10 | M11: ='Monthly operating and hiring fo'!M6*'Pricing and operating assumptio'!B17 -> 10
A12: Extra successful fixes | B12: ='Monthly operating and hiring fo'!B5*'Monthly operating and hiring fo'!B7 -> 0 | C12: ='Monthly operating and hiring fo'!C5*'Monthly operating and hiring fo'!C7 -> 0 | D12: ='Monthly operating and hiring fo'!D5*'Monthly operating and hiring fo'!D7 -> 0 | E12: ='Monthly operating and hiring fo'!E5*'Monthly operating and hiring fo'!E7 -> 0 | F12: ='Monthly operating and hiring fo'!F5*'Monthly operating and hiring fo'!F7 -> 0 | G12: ='Monthly operating and hiring fo'!G5*'Monthly operating and hiring fo'!G7 -> 0 | H12: ='Monthly operating and hiring fo'!H5*'Monthly operating and hiring fo'!H7 -> 0 | I12: ='Monthly operating and hiring fo'!I5*'Monthly operating and hiring fo'!I7 -> 0 | ... M12: ='Monthly operating and hiring fo'!M5*'Monthly operating and hiring fo'!M7 -> 0
A13: Team subscription revenue | B13: ='Monthly operating and hiring fo'!B5*'Pricing and operating assumptio'!B5 -> 0 | C13: ='Monthly operating and hiring fo'!C5*'Pricing and operating assumptio'!B5 -> 199 | D13: ='Monthly operating and hiring fo'!D5*'Pricing and operating assumptio'!B5 -> 398 | E13: ='Monthly operating and hiring fo'!E5*'Pricing and operating assumptio'!B5 -> 597 | F13: ='Monthly operating and hiring fo'!F5*'Pricing and operating assumptio'!B5 -> 796 | G13: ='Monthly operating and hiring fo'!G5*'Pricing and operating assumptio'!B5 -> 995 | H13: ='Monthly operating and hiring fo'!H5*'Pricing and operating assumptio'!B5 -> 1592 | I13: ='Monthly operating and hiring fo'!I5*'Pricing and operating assumptio'!B5 -> 2189 | J13: ='Monthly operating and hiring fo'!J5*'Pricing and operating assumptio'!B5 -> 2985 | K13: ='Monthly operating and hiring fo'!K5*'Pricing and operating assumptio'!B5 -> 3980 | L13: ='Monthly operating and hiring fo'!L5*'Pricing and operating assumptio'!B5 -> 4975 | M13: ='Monthly operating and hiring fo'!M5*'Pricing and operating assumptio'!B5 -> 5970
A14: Extra fix revenue | B14: ='Monthly operating and hiring fo'!B12*'Pricing and operating assumptio'!B7 -> 0 | C14: ='Monthly operating and hiring fo'!C12*'Pricing and operating assumptio'!B7 -> 0 | D14: ='Monthly operating and hiring fo'!D12*'Pricing and operating assumptio'!B7 -> 0 | E14: ='Monthly operating and hiring fo'!E12*'Pricing and operating assumptio'!B7 -> 0 | F14: ='Monthly operating and hiring fo'!F12*'Pricing and operating assumptio'!B7 -> 0 | G14: ='Monthly operating and hiring fo'!G12*'Pricing and operating assumptio'!B7 -> 0 | H14: ='Monthly operating and hiring fo'!H12*'Pricing and operating assumptio'!B7 -> 0 | I14: ='Monthly operating and hiring fo'!I12*'Pricing and operating assumptio'!B7 -> 0 | J14: ='Monthly operating and hiring fo'!J12*'Pricing and operating assumptio'!B7 -> 0 | K14: ='Monthly operating and hiring fo'!K12*'Pricing and operating assumptio'!B7 -> 0 | L14: ='Monthly operating and hiring fo'!L12*'Pricing and operating assumptio'!B7 -> 0 | M14: ='Monthly operating and hiring fo'!M12*'Pricing and operating assumptio'!B7 -> 0
A15: Pay per fix revenue | B15: ='Monthly operating and hiring fo'!B8*'Pricing and operating assumptio'!B8 -> 0 | C15: ='Monthly operating and hiring fo'!C8*'Pricing and operating assumptio'!B8 -> 0 | D15: ='Monthly operating and hiring fo'!D8*'Pricing and operating assumptio'!B8 -> 0 | E15: ='Monthly operating and hiring fo'!E8*'Pricing and operating assumptio'!B8 -> 0 | F15: ='Monthly operating and hiring fo'!F8*'Pricing and operating assumptio'!B8 -> 0 | G15: ='Monthly operating and hiring fo'!G8*'Pricing and operating assumptio'!B8 -> 0 | H15: ='Monthly operating and hiring fo'!H8*'Pricing and operating assumptio'!B8 -> 0 | I15: ='Monthly operating and hiring fo'!I8*'Pricing and operating assumptio'!B8 -> 0 | J15: ='Monthly operating and hiring fo'!J8*'Pricing and operating assumptio'!B8 -> 0 | K15: ='Monthly operating and hiring fo'!K8*'Pricing and operating assumptio'!B8 -> 0 | L15: ='Monthly operating and hiring fo'!L8*'Pricing and operating assumptio'!B8 -> 0 | M15: ='Monthly operating and hiring fo'!M8*'Pricing and operating assumptio'!B8 -> 0
A16: Revenue | B16: ='Monthly operating and hiring fo'!B13+'Monthly operating and hiring fo'!B14+'Monthly operating and hiring fo'!B15 -> 0 | C16: ='Monthly operating and hiring fo'!C13+'Monthly operating and hiring fo'!C14+'Monthly operating and hiring fo'!C15 -> 199 | D16: ='Monthly operating and hiring fo'!D13+'Monthly operating and hiring fo'!D14+'Monthly operating and hiring fo'!D15 -> 398 | E16: ='Monthly operating and hiring fo'!E13+'Monthly operating and hiring fo'!E14+'Monthly operating and hiring fo'!E15 -> 597 | F16: ='Monthly operating and hiring fo'!F13+'Monthly operating and hiring fo'!F14+'Monthly operating and hiring fo'!F15 -> 796 | G16: ='Monthly operating and hiring fo'!G13+'Monthly operating and hiring fo'!G14+'Monthly operating and hiring fo'!G15 -> 995 | H16: ='Monthly operating and hiring fo'!H13+'Monthly operating and hiring fo'!H14+'Monthly operating and hiring fo'!H15 -> 1592 | I16: ='Monthly operating and hiring fo'!I13+'Monthly operating and hiring fo'!I14+'Monthly operating and hiring fo'!I15 -> 2189 | ... M16: ='Monthly operating and hiring fo'!M13+'Monthly operating and hiring fo'!M14+'Monthly operating and hiring fo'!M15 -> 5970
A17: Paid delivery cost | B17: =('Monthly operating and hiring fo'!B10+'Monthly operating and hiring fo'!B12+'Monthly operating and hiring fo'!B8)*'Pricing and operating assumptio'!B9 -> 0 | C17: =('Monthly operating and hiring fo'!C10+'Monthly operating and hiring fo'!C12+'Monthly operating and hiring fo'!C8)*'Pricing and operating assumptio'!B9 -> 15 | D17: =('Monthly operating and hiring fo'!D10+'Monthly operating and hiring fo'!D12+'Monthly operating and hiring fo'!D8)*'Pricing and operating assumptio'!B9 -> 30 | E17: =('Monthly operating and hiring fo'!E10+'Monthly operating and hiring fo'!E12+'Monthly operating and hiring fo'!E8)*'Pricing and operating assumptio'!B9 -> 45 | F17: =('Monthly operating and hiring fo'!F10+'Monthly operating and hiring fo'!F12+'Monthly operating and hiring fo'!F8)*'Pricing and operating assumptio'!B9 -> 60 | G17: =('Monthly operating and hiring fo'!G10+'Monthly operating and hiring fo'!G12+'Monthly operating and hiring fo'!G8)*'Pricing and operating assumptio'!B9 -> 75 | H17: =('Monthly operating and hiring fo'!H10+'Monthly operating and hiring fo'!H12+'Monthly operating and hiring fo'!H8)*'Pricing and operating assumptio'!B9 -> 120 | I17: =('Monthly operating and hiring fo'!I10+'Monthly operating and hiring fo'!I12+'Monthly operating and hiring fo'!I8)*'Pricing and operating assumptio'!B9 -> 165 | J17: =('Monthly operating and hiring fo'!J10+'Monthly operating and hiring fo'!J12+'Monthly operating and hiring fo'!J8)*'Pricing and operating assumptio'!B9 -> 225 | K17: =('Monthly operating and hiring fo'!K10+'Monthly operating and hiring fo'!K12+'Monthly operating and hiring fo'!K8)*'Pricing and operating assumptio'!B9 -> 300 | L17: =('Monthly operating and hiring fo'!L10+'Monthly operating and hiring fo'!L12+'Monthly operating and hiring fo'!L8)*'Pricing and operating assumptio'!B9 -> 375 | M17: =('Monthly operating and hiring fo'!M10+'Monthly operating and hiring fo'!M12+'Monthly operating and hiring fo'!M8)*'Pricing and operating assumptio'!B9 -> 450
A18: Gross profit | B18: ='Monthly operating and hiring fo'!B16-'Monthly operating and hiring fo'!B17 -> 0 | C18: ='Monthly operating and hiring fo'!C16-'Monthly operating and hiring fo'!C17 -> 184 | D18: ='Monthly operating and hiring fo'!D16-'Monthly operating and hiring fo'!D17 -> 368 | E18: ='Monthly operating and hiring fo'!E16-'Monthly operating and hiring fo'!E17 -> 552 | F18: ='Monthly operating and hiring fo'!F16-'Monthly operating and hiring fo'!F17 -> 736 | G18: ='Monthly operating and hiring fo'!G16-'Monthly operating and hiring fo'!G17 -> 920 | H18: ='Monthly operating and hiring fo'!H16-'Monthly operating and hiring fo'!H17 -> 1472 | I18: ='Monthly operating and hiring fo'!I16-'Monthly operating and hiring fo'!I17 -> 2024 | ... M18: ='Monthly operating and hiring fo'!M16-'Monthly operating and hiring fo'!M17 -> 5520
A19: Gross margin | B19: =IFERROR('Monthly operating and hiring fo'!B18/'Monthly operating and hiring fo'!B16,"") | C19: =IFERROR('Monthly operating and hiring fo'!C18/'Monthly operating and hiring fo'!C16,"") -> 0.92462312 | D19: =IFERROR('Monthly operating and hiring fo'!D18/'Monthly operating and hiring fo'!D16,"") -> 0.92462312 | E19: =IFERROR('Monthly operating and hiring fo'!E18/'Monthly operating and hiring fo'!E16,"") -> 0.92462312 | F19: =IFERROR('Monthly operating and hiring fo'!F18/'Monthly operating and hiring fo'!F16,"") -> 0.92462312 | G19: =IFERROR('Monthly operating and hiring fo'!G18/'Monthly operating and hiring fo'!G16,"") -> 0.92462312 | H19: =IFERROR('Monthly operating and hiring fo'!H18/'Monthly operating and hiring fo'!H16,"") -> 0.92462312 | I19: =IFERROR('Monthly operating and hiring fo'!I18/'Monthly operating and hiring fo'!I16,"") -> 0.92462312 | ... M19: =IFERROR('Monthly operating and hiring fo'!M18/'Monthly operating and hiring fo'!M16,"") -> 0.92462312
A20: Free project cost | B20: ='Monthly operating and hiring fo'!B11*'Pricing and operating assumptio'!B9 -> 4.5 | C20: ='Monthly operating and hiring fo'!C11*'Pricing and operating assumptio'!B9 -> 9 | D20: ='Monthly operating and hiring fo'!D11*'Pricing and operating assumptio'!B9 -> 15 | E20: ='Monthly operating and hiring fo'!E11*'Pricing and operating assumptio'!B9 -> 15 | F20: ='Monthly operating and hiring fo'!F11*'Pricing and operating assumptio'!B9 -> 15 | G20: ='Monthly operating and hiring fo'!G11*'Pricing and operating assumptio'!B9 -> 15 | H20: ='Monthly operating and hiring fo'!H11*'Pricing and operating assumptio'!B9 -> 15 | I20: ='Monthly operating and hiring fo'!I11*'Pricing and operating assumptio'!B9 -> 15 | J20: ='Monthly operating and hiring fo'!J11*'Pricing and operating assumptio'!B9 -> 15 | K20: ='Monthly operating and hiring fo'!K11*'Pricing and operating assumptio'!B9 -> 15 | L20: ='Monthly operating and hiring fo'!L11*'Pricing and operating assumptio'!B9 -> 15 | M20: ='Monthly operating and hiring fo'!M11*'Pricing and operating assumptio'!B9 -> 15
A21: Fixed overhead | B21: ='Pricing and operating assumptio'!B11+'Pricing and operating assumptio'!B12 -> 150 | C21: ='Pricing and operating assumptio'!B11+'Pricing and operating assumptio'!B12 -> 150 | D21: ='Pricing and operating assumptio'!B11+'Pricing and operating assumptio'!B12 -> 150 | E21: ='Pricing and operating assumptio'!B11+'Pricing and operating assumptio'!B12 -> 150 | F21: ='Pricing and operating assumptio'!B11+'Pricing and operating assumptio'!B12 -> 150 | G21: ='Pricing and operating assumptio'!B11+'Pricing and operating assumptio'!B12 -> 150 | H21: ='Pricing and operating assumptio'!B11+'Pricing and operating assumptio'!B12 -> 150 | I21: ='Pricing and operating assumptio'!B11+'Pricing and operating assumptio'!B12 -> 150 | J21: ='Pricing and operating assumptio'!B11+'Pricing and operating assumptio'!B12 -> 150 | K21: ='Pricing and operating assumptio'!B11+'Pricing and operating assumptio'!B12 -> 150 | L21: ='Pricing and operating assumptio'!B11+'Pricing and operating assumptio'!B12 -> 150 | M21: ='Pricing and operating assumptio'!B11+'Pricing and operating assumptio'!B12 -> 150
A22: Founder pay | B22: =IF(IF(IF(ISERROR('Monthly operating and hiring fo'!B9>='Pricing and operating assumptio'!B14),'Monthly operating and hiring fo'!B9>='Pricing and operating assumptio'!B14,IF(OR('Monthly operating and hiring fo'!B9="",'Pricing and operating assumptio'!B14=""),"",'Monthly operating and hiring fo'!B9>='Pricing and operating assumptio'!B14))="",FALSE,IF(ISERROR('Monthly operating and hiring fo'!B9>='Pricing and operating assumptio'!B14),'Monthly operating and hiring fo'!B9>='Pricing and operating assumptio'!B14,IF(OR('Monthly operating and hiring fo'!B9="",'Pricing and operating assumptio'!B14=""),"",'Monthly operating and hiring fo'!B9>='Pricing and operating assumptio'!B14))),IF('Pricing and operating assumptio'!B13="","",'Pricing and operating assumptio'!B13),0) -> 0 | C22: =IF(IF(IF(ISERROR('Monthly operating and hiring fo'!C9>='Pricing and operating assumptio'!B14),'Monthly operating and hiring fo'!C9>='Pricing and operating assumptio'!B14,IF(OR('Monthly operating and hiring fo'!C9="",'Pricing and operating assumptio'!B14=""),"",'Monthly operating and hiring fo'!C9>='Pricing and operating assumptio'!B14))="",FALSE,IF(ISERROR('Monthly operating and hiring fo'!C9>='Pricing and operating assumptio'!B14),'Monthly operating and hiring fo'!C9>='Pricing and operating assumptio'!B14,IF(OR('Monthly operating and hiring fo'!C9="",'Pricing and operating assumptio'!B14=""),"",'Monthly operating and hiring fo'!C9>='Pricing and operating assumptio'!B14))),IF('Pricing and operating assumptio'!B13="","",'Pricing and operating assumptio'!B13),0) -> 0 | D22: =IF(IF(IF(ISERROR('Monthly operating and hiring fo'!D9>='Pricing and operating assumptio'!B14),'Monthly operating and hiring fo'!D9>='Pricing and operating assumptio'!B14,IF(OR('Monthly operating and hiring fo'!D9="",'Pricing and operating assumptio'!B14=""),"",'Monthly operating and hiring fo'!D9>='Pricing and operating assumptio'!B14))="",FALSE,IF(ISERROR('Monthly operating and hiring fo'!D9>='Pricing and operating assumptio'!B14),'Monthly operating and hiring fo'!D9>='Pricing and operating assumptio'!B14,IF(OR('Monthly operating and hiring fo'!D9="",'Pricing and operating assumptio'!B14=""),"",'Monthly operating and hiring fo'!D9>='Pricing and operating assumptio'!B14))),IF('Pricing and operating assumptio'!B13="","",'Pricing and operating assumptio'!B13),0) -> 0 | E22: =IF(IF(IF(ISERROR('Monthly operating and hiring fo'!E9>='Pricing and operating assumptio'!B14),'Monthly operating and hiring fo'!E9>='Pricing and operating assumptio'!B14,IF(OR('Monthly operating and hiring fo'!E9="",'Pricing and operating assumptio'!B14=""),"",'Monthly operating and hiring fo'!E9>='Pricing and operating assumptio'!B14))="",FALSE,IF(ISERROR('Monthly operating and hiring fo'!E9>='Pricing and operating assumptio'!B14),'Monthly operating and hiring fo'!E9>='Pricing and operating assumptio'!B14,IF(OR('Monthly operating and hiring fo'!E9="",'Pricing and operating assumptio'!B14=""),"",'Monthly operating and hiring fo'!E9>='Pricing and operating assumptio'!B14))),IF('Pricing and operating assumptio'!B13="","",'Pricing and operating assumptio'!B13),0) -> 0 | F22: =IF(IF(IF(ISERROR('Monthly operating and hiring fo'!F9>='Pricing and operating assumptio'!B14),'Monthly operating and hiring fo'!F9>='Pricing and operating assumptio'!B14,IF(OR('Monthly operating and hiring fo'!F9="",'Pricing and operating assumptio'!B14=""),"",'Monthly operating and hiring fo'!F9>='Pricing and operating assumptio'!B14))="",FALSE,IF(ISERROR('Monthly operating and hiring fo'!F9>='Pricing and operating assumptio'!B14),'Monthly operating and hiring fo'!F9>='Pricing and operating assumptio'!B14,IF(OR('Monthly operating and hiring fo'!F9="",'Pricing and operating assumptio'!B14=""),"",'Monthly operating and hiring fo'!F9>='Pricing and operating assumptio'!B14))),IF('Pricing and operating assumptio'!B13="","",'Pricing and operating assumptio'!B13),0) -> 0 | G22: =IF(IF(IF(ISERROR('Monthly operating and hiring fo'!G9>='Pricing and operating assumptio'!B14),'Monthly operating and hiring fo'!G9>='Pricing and operating assumptio'!B14,IF(OR('Monthly operating and hiring fo'!G9="",'Pricing and operating assumptio'!B14=""),"",'Monthly operating and hiring fo'!G9>='Pricing and operating assumptio'!B14))="",FALSE,IF(ISERROR('Monthly operating and hiring fo'!G9>='Pricing and operating assumptio'!B14),'Monthly operating and hiring fo'!G9>='Pricing and operating assumptio'!B14,IF(OR('Monthly operating and hiring fo'!G9="",'Pricing and operating assumptio'!B14=""),"",'Monthly operating and hiring fo'!G9>='Pricing and operating assumptio'!B14))),IF('Pricing and operating assumptio'!B13="","",'Pricing and operating assumptio'!B13),0) -> 0 | H22: =IF(IF(IF(ISERROR('Monthly operating and hiring fo'!H9>='Pricing and operating assumptio'!B14),'Monthly operating and hiring fo'!H9>='Pricing and operating assumptio'!B14,IF(OR('Monthly operating and hiring fo'!H9="",'Pricing and operating assumptio'!B14=""),"",'Monthly operating and hiring fo'!H9>='Pricing and operating assumptio'!B14))="",FALSE,IF(ISERROR('Monthly operating and hiring fo'!H9>='Pricing and operating assumptio'!B14),'Monthly operating and hiring fo'!H9>='Pricing and operating assumptio'!B14,IF(OR('Monthly operating and hiring fo'!H9="",'Pricing and operating assumptio'!B14=""),"",'Monthly operating and hiring fo'!H9>='Pricing and operating assumptio'!B14))),IF('Pricing and operating assumptio'!B13="","",'Pricing and operating assumptio'!B13),0) -> 4000 | I22: =IF(IF(IF(ISERROR('Monthly operating and hiring fo'!I9>='Pricing and operating assumptio'!B14),'Monthly operating and hiring fo'!I9>='Pricing and operating assumptio'!B14,IF(OR('Monthly operating and hiring fo'!I9="",'Pricing and operating assumptio'!B14=""),"",'Monthly operating and hiring fo'!I9>='Pricing and operating assumptio'!B14))="",FALSE,IF(ISERROR('Monthly operating and hiring fo'!I9>='Pricing and operating assumptio'!B14),'Monthly operating and hiring fo'!I9>='Pricing and operating assumptio'!B14,IF(OR('Monthly operating and hiring fo'!I9="",'Pricing and operating assumptio'!B14=""),"",'Monthly operating and hiring fo'!I9>='Pricing and operating assumptio'!B14))),IF('Pricing and operating assumptio'!B13="","",'Pricing and operating assumptio'!B13),0) -> 4000 | J22: =IF(IF(IF(ISERROR('Monthly operating and hiring fo'!J9>='Pricing and operating assumptio'!B14),'Monthly operating and hiring fo'!J9>='Pricing and operating assumptio'!B14,IF(OR('Monthly operating and hiring fo'!J9="",'Pricing and operating assumptio'!B14=""),"",'Monthly operating and hiring fo'!J9>='Pricing and operating assumptio'!B14))="",FALSE,IF(ISERROR('Monthly operating and hiring fo'!J9>='Pricing and operating assumptio'!B14),'Monthly operating and hiring fo'!J9>='Pricing and operating assumptio'!B14,IF(OR('Monthly operating and hiring fo'!J9="",'Pricing and operating assumptio'!B14=""),"",'Monthly operating and hiring fo'!J9>='Pricing and operating assumptio'!B14))),IF('Pricing and operating assumptio'!B13="","",'Pricing and operating assumptio'!B13),0) -> 4000 | K22: =IF(IF(IF(ISERROR('Monthly operating and hiring fo'!K9>='Pricing and operating assumptio'!B14),'Monthly operating and hiring fo'!K9>='Pricing and operating assumptio'!B14,IF(OR('Monthly operating and hiring fo'!K9="",'Pricing and operating assumptio'!B14=""),"",'Monthly operating and hiring fo'!K9>='Pricing and operating assumptio'!B14))="",FALSE,IF(ISERROR('Monthly operating and hiring fo'!K9>='Pricing and operating assumptio'!B14),'Monthly operating and hiring fo'!K9>='Pricing and operating assumptio'!B14,IF(OR('Monthly operating and hiring fo'!K9="",'Pricing and operating assumptio'!B14=""),"",'Monthly operating and hiring fo'!K9>='Pricing and operating assumptio'!B14))),IF('Pricing and operating assumptio'!B13="","",'Pricing and operating assumptio'!B13),0) -> 4000 | L22: =IF(IF(IF(ISERROR('Monthly operating and hiring fo'!L9>='Pricing and operating assumptio'!B14),'Monthly operating and hiring fo'!L9>='Pricing and operating assumptio'!B14,IF(OR('Monthly operating and hiring fo'!L9="",'Pricing and operating assumptio'!B14=""),"",'Monthly operating and hiring fo'!L9>='Pricing and operating assumptio'!B14))="",FALSE,IF(ISERROR('Monthly operating and hiring fo'!L9>='Pricing and operating assumptio'!B14),'Monthly operating and hiring fo'!L9>='Pricing and operating assumptio'!B14,IF(OR('Monthly operating and hiring fo'!L9="",'Pricing and operating assumptio'!B14=""),"",'Monthly operating and hiring fo'!L9>='Pricing and operating assumptio'!B14))),IF('Pricing and operating assumptio'!B13="","",'Pricing and operating assumptio'!B13),0) -> 4000 | M22: =IF(IF(IF(ISERROR('Monthly operating and hiring fo'!M9>='Pricing and operating assumptio'!B14),'Monthly operating and hiring fo'!M9>='Pricing and operating assumptio'!B14,IF(OR('Monthly operating and hiring fo'!M9="",'Pricing and operating assumptio'!B14=""),"",'Monthly operating and hiring fo'!M9>='Pricing and operating assumptio'!B14))="",FALSE,IF(ISERROR('Monthly operating and hiring fo'!M9>='Pricing and operating assumptio'!B14),'Monthly operating and hiring fo'!M9>='Pricing and operating assumptio'!B14,IF(OR('Monthly operating and hiring fo'!M9="",'Pricing and operating assumptio'!B14=""),"",'Monthly operating and hiring fo'!M9>='Pricing and operating assumptio'!B14))),IF('Pricing and operating assumptio'!B13="","",'Pricing and operating assumptio'!B13),0) -> 4000
A23: Cash flow before hire | B23: ='Monthly operating and hiring fo'!B18-'Monthly operating and hiring fo'!B20-'Monthly operating and hiring fo'!B21-'Monthly operating and hiring fo'!B22 -> -154.5 | C23: ='Monthly operating and hiring fo'!C18-'Monthly operating and hiring fo'!C20-'Monthly operating and hiring fo'!C21-'Monthly operating and hiring fo'!C22 -> 25 | D23: ='Monthly operating and hiring fo'!D18-'Monthly operating and hiring fo'!D20-'Monthly operating and hiring fo'!D21-'Monthly operating and hiring fo'!D22 -> 203 | E23: ='Monthly operating and hiring fo'!E18-'Monthly operating and hiring fo'!E20-'Monthly operating and hiring fo'!E21-'Monthly operating and hiring fo'!E22 -> 387 | F23: ='Monthly operating and hiring fo'!F18-'Monthly operating and hiring fo'!F20-'Monthly operating and hiring fo'!F21-'Monthly operating and hiring fo'!F22 -> 571 | G23: ='Monthly operating and hiring fo'!G18-'Monthly operating and hiring fo'!G20-'Monthly operating and hiring fo'!G21-'Monthly operating and hiring fo'!G22 -> 755 | H23: ='Monthly operating and hiring fo'!H18-'Monthly operating and hiring fo'!H20-'Monthly operating and hiring fo'!H21-'Monthly operating and hiring fo'!H22 -> -2693 | I23: ='Monthly operating and hiring fo'!I18-'Monthly operating and hiring fo'!I20-'Monthly operating and hiring fo'!I21-'Monthly operating and hiring fo'!I22 -> -2141 | ... M23: ='Monthly operating and hiring fo'!M18-'Monthly operating and hiring fo'!M20-'Monthly operating and hiring fo'!M21-'Monthly operating and hiring fo'!M22 -> 1355
A24: Team contribution | B24: ='Pricing and operating assumptio'!B5-'Pricing and operating assumptio'!B6*'Pricing and operating assumptio'!B9 -> 184 | C24: ='Pricing and operating assumptio'!B5-'Pricing and operating assumptio'!B6*'Pricing and operating assumptio'!B9 -> 184 | D24: ='Pricing and operating assumptio'!B5-'Pricing and operating assumptio'!B6*'Pricing and operating assumptio'!B9 -> 184 | E24: ='Pricing and operating assumptio'!B5-'Pricing and operating assumptio'!B6*'Pricing and operating assumptio'!B9 -> 184 | F24: ='Pricing and operating assumptio'!B5-'Pricing and operating assumptio'!B6*'Pricing and operating assumptio'!B9 -> 184 | G24: ='Pricing and operating assumptio'!B5-'Pricing and operating assumptio'!B6*'Pricing and operating assumptio'!B9 -> 184 | H24: ='Pricing and operating assumptio'!B5-'Pricing and operating assumptio'!B6*'Pricing and operating assumptio'!B9 -> 184 | I24: ='Pricing and operating assumptio'!B5-'Pricing and operating assumptio'!B6*'Pricing and operating assumptio'!B9 -> 184 | J24: ='Pricing and operating assumptio'!B5-'Pricing and operating assumptio'!B6*'Pricing and operating assumptio'!B9 -> 184 | K24: ='Pricing and operating assumptio'!B5-'Pricing and operating assumptio'!B6*'Pricing and operating assumptio'!B9 -> 184 | L24: ='Pricing and operating assumptio'!B5-'Pricing and operating assumptio'!B6*'Pricing and operating assumptio'!B9 -> 184 | M24: ='Pricing and operating assumptio'!B5-'Pricing and operating assumptio'!B6*'Pricing and operating assumptio'!B9 -> 184
A25: Break-even teams | B25: =CEILING(('Monthly operating and hiring fo'!B21+'Monthly operating and hiring fo'!B20+'Monthly operating and hiring fo'!B22)/'Monthly operating and hiring fo'!B24,1) -> 1 | C25: =CEILING(('Monthly operating and hiring fo'!C21+'Monthly operating and hiring fo'!C20+'Monthly operating and hiring fo'!C22)/'Monthly operating and hiring fo'!C24,1) -> 1 | D25: =CEILING(('Monthly operating and hiring fo'!D21+'Monthly operating and hiring fo'!D20+'Monthly operating and hiring fo'!D22)/'Monthly operating and hiring fo'!D24,1) -> 1 | E25: =CEILING(('Monthly operating and hiring fo'!E21+'Monthly operating and hiring fo'!E20+'Monthly operating and hiring fo'!E22)/'Monthly operating and hiring fo'!E24,1) -> 1 | F25: =CEILING(('Monthly operating and hiring fo'!F21+'Monthly operating and hiring fo'!F20+'Monthly operating and hiring fo'!F22)/'Monthly operating and hiring fo'!F24,1) -> 1 | G25: =CEILING(('Monthly operating and hiring fo'!G21+'Monthly operating and hiring fo'!G20+'Monthly operating and hiring fo'!G22)/'Monthly operating and hiring fo'!G24,1) -> 1 | H25: =CEILING(('Monthly operating and hiring fo'!H21+'Monthly operating and hiring fo'!H20+'Monthly operating and hiring fo'!H22)/'Monthly operating and hiring fo'!H24,1) -> 23 | I25: =CEILING(('Monthly operating and hiring fo'!I21+'Monthly operating and hiring fo'!I20+'Monthly operating and hiring fo'!I22)/'Monthly operating and hiring fo'!I24,1) -> 23 | ... M25: =CEILING(('Monthly operating and hiring fo'!M21+'Monthly operating and hiring fo'!M20+'Monthly operating and hiring fo'!M22)/'Monthly operating and hiring fo'!M24,1) -> 23
A26: Teams needed with engineer | B26: =CEILING(('Monthly operating and hiring fo'!B21+'Monthly operating and hiring fo'!B20+'Monthly operating and hiring fo'!B22+'Pricing and operating assumptio'!B15)/'Monthly operating and hiring fo'!B24,1) -> 34 | C26: =CEILING(('Monthly operating and hiring fo'!C21+'Monthly operating and hiring fo'!C20+'Monthly operating and hiring fo'!C22+'Pricing and operating assumptio'!B15)/'Monthly operating and hiring fo'!C24,1) -> 34 | D26: =CEILING(('Monthly operating and hiring fo'!D21+'Monthly operating and hiring fo'!D20+'Monthly operating and hiring fo'!D22+'Pricing and operating assumptio'!B15)/'Monthly operating and hiring fo'!D24,1) -> 34 | E26: =CEILING(('Monthly operating and hiring fo'!E21+'Monthly operating and hiring fo'!E20+'Monthly operating and hiring fo'!E22+'Pricing and operating assumptio'!B15)/'Monthly operating and hiring fo'!E24,1) -> 34 | F26: =CEILING(('Monthly operating and hiring fo'!F21+'Monthly operating and hiring fo'!F20+'Monthly operating and hiring fo'!F22+'Pricing and operating assumptio'!B15)/'Monthly operating and hiring fo'!F24,1) -> 34 | G26: =CEILING(('Monthly operating and hiring fo'!G21+'Monthly operating and hiring fo'!G20+'Monthly operating and hiring fo'!G22+'Pricing and operating assumptio'!B15)/'Monthly operating and hiring fo'!G24,1) -> 34 | H26: =CEILING(('Monthly operating and hiring fo'!H21+'Monthly operating and hiring fo'!H20+'Monthly operating and hiring fo'!H22+'Pricing and operating assumptio'!B15)/'Monthly operating and hiring fo'!H24,1) -> 56 | I26: =CEILING(('Monthly operating and hiring fo'!I21+'Monthly operating and hiring fo'!I20+'Monthly operating and hiring fo'!I22+'Pricing and operating assumptio'!B15)/'Monthly operating and hiring fo'!I24,1) -> 56 | J26: =CEILING(('Monthly operating and hiring fo'!J21+'Monthly operating and hiring fo'!J20+'Monthly operating and hiring fo'!J22+'Pricing and operating assumptio'!B15)/'Monthly operating and hiring fo'!J24,1) -> 56 | K26: =CEILING(('Monthly operating and hiring fo'!K21+'Monthly operating and hiring fo'!K20+'Monthly operating and hiring fo'!K22+'Pricing and operating assumptio'!B15)/'Monthly operating and hiring fo'!K24,1) -> 56 | L26: =CEILING(('Monthly operating and hiring fo'!L21+'Monthly operating and hiring fo'!L20+'Monthly operating and hiring fo'!L22+'Pricing and operating assumptio'!B15)/'Monthly operating and hiring fo'!L24,1) -> 56 | M26: =CEILING(('Monthly operating and hiring fo'!M21+'Monthly operating and hiring fo'!M20+'Monthly operating and hiring fo'!M22+'Pricing and operating assumptio'!B15)/'Monthly operating and hiring fo'!M24,1) -> 56
A27: Engineer hired | B27: =IF(IF(IF(ISERROR('Monthly operating and hiring fo'!B9<'Pricing and operating assumptio'!B16),'Monthly operating and hiring fo'!B9<'Pricing and operating assumptio'!B16,IF(OR('Monthly operating and hiring fo'!B9="",'Pricing and operating assumptio'!B16=""),"",'Monthly operating and hiring fo'!B9<'Pricing and operating assumptio'!B16))="",FALSE,IF(ISERROR('Monthly operating and hiring fo'!B9<'Pricing and operating assumptio'!B16),'Monthly operating and hiring fo'!B9<'Pricing and operating assumptio'!B16,IF(OR('Monthly operating and hiring fo'!B9="",'Pricing and operating assumptio'!B16=""),"",'Monthly operating and hiring fo'!B9<'Pricing and operating assumptio'!B16))),0,IF(IF(IF(IFERROR(IF(ISERROR('Model inputs'!B24=1),'Model inputs'!B24=1,IF('Model inputs'!B24="","",'Model inputs'!B24=1))=TRUE,FALSE),TRUE,IF(IFERROR('Model inputs'!B167=TRUE,FALSE),TRUE,IF(OR(IF(ISERROR('Model inputs'!B24=1),'Model inputs'!B24=1,IF('Model inputs'!B24="","",'Model inputs'!B24=1))="",'Model inputs'!B167=""),"",OR(IF(ISERROR('Model inputs'!B24=1),'Model inputs'!B24=1,IF('Model inputs'!B24="","",'Model inputs'!B24=1)),'Model inputs'!B167))))="",FALSE,IF(IFERROR(IF(ISERROR('Model inputs'!B24=1),'Model inputs'!B24=1,IF('Model inputs'!B24="","",'Model inputs'!B24=1))=TRUE,FALSE),TRUE,IF(IFERROR('Model inputs'!B167=TRUE,FALSE),TRUE,IF(OR(IF(ISERROR('Model inputs'!B24=1),'Model inputs'!B24=1,IF('Model inputs'!B24="","",'Model inputs'!B24=1))="",'Model inputs'!B167=""),"",OR(IF(ISERROR('Model inputs'!B24=1),'Model inputs'!B24=1,IF('Model inputs'!B24="","",'Model inputs'!B24=1)),'Model inputs'!B167))))),1,0)) -> 0 | C27: =IF(IF(IF(ISERROR('Monthly operating and hiring fo'!C9<'Pricing and operating assumptio'!B16),'Monthly operating and hiring fo'!C9<'Pricing and operating assumptio'!B16,IF(OR('Monthly operating and hiring fo'!C9="",'Pricing and operating assumptio'!B16=""),"",'Monthly operating and hiring fo'!C9<'Pricing and operating assumptio'!B16))="",FALSE,IF(ISERROR('Monthly operating and hiring fo'!C9<'Pricing and operating assumptio'!B16),'Monthly operating and hiring fo'!C9<'Pricing and operating assumptio'!B16,IF(OR('Monthly operating and hiring fo'!C9="",'Pricing and operating assumptio'!B16=""),"",'Monthly operating and hiring fo'!C9<'Pricing and operating assumptio'!B16))),0,IF(IF(IF(IFERROR('Model inputs'!B168=TRUE,FALSE),TRUE,IF(IFERROR('Model inputs'!B169=TRUE,FALSE),TRUE,IF(OR('Model inputs'!B168="",'Model inputs'!B169=""),"",OR('Model inputs'!B168,'Model inputs'!B169))))="",FALSE,IF(IFERROR('Model inputs'!B168=TRUE,FALSE),TRUE,IF(IFERROR('Model inputs'!B169=TRUE,FALSE),TRUE,IF(OR('Model inputs'!B168="",'Model inputs'!B169=""),"",OR('Model inputs'!B168,'Model inputs'!B169))))),1,0)) -> 0 | D27: =IF(IF(IF(ISERROR('Monthly operating and hiring fo'!D9<'Pricing and operating assumptio'!B16),'Monthly operating and hiring fo'!D9<'Pricing and operating assumptio'!B16,IF(OR('Monthly operating and hiring fo'!D9="",'Pricing and operating assumptio'!B16=""),"",'Monthly operating and hiring fo'!D9<'Pricing and operating assumptio'!B16))="",FALSE,IF(ISERROR('Monthly operating and hiring fo'!D9<'Pricing and operating assumptio'!B16),'Monthly operating and hiring fo'!D9<'Pricing and operating assumptio'!B16,IF(OR('Monthly operating and hiring fo'!D9="",'Pricing and operating assumptio'!B16=""),"",'Monthly operating and hiring fo'!D9<'Pricing and operating assumptio'!B16))),0,IF(IF(IF(IFERROR('Model inputs'!B170=TRUE,FALSE),TRUE,IF(IFERROR('Model inputs'!B171=TRUE,FALSE),TRUE,IF(OR('Model inputs'!B170="",'Model inputs'!B171=""),"",OR('Model inputs'!B170,'Model inputs'!B171))))="",FALSE,IF(IFERROR('Model inputs'!B170=TRUE,FALSE),TRUE,IF(IFERROR('Model inputs'!B171=TRUE,FALSE),TRUE,IF(OR('Model inputs'!B170="",'Model inputs'!B171=""),"",OR('Model inputs'!B170,'Model inputs'!B171))))),1,0)) -> 0 | E27: =IF(IF(IF(ISERROR('Monthly operating and hiring fo'!E9<'Pricing and operating assumptio'!B16),'Monthly operating and hiring fo'!E9<'Pricing and operating assumptio'!B16,IF(OR('Monthly operating and hiring fo'!E9="",'Pricing and operating assumptio'!B16=""),"",'Monthly operating and hiring fo'!E9<'Pricing and operating assumptio'!B16))="",FALSE,IF(ISERROR('Monthly operating and hiring fo'!E9<'Pricing and operating assumptio'!B16),'Monthly operating and hiring fo'!E9<'Pricing and operating assumptio'!B16,IF(OR('Monthly operating and hiring fo'!E9="",'Pricing and operating assumptio'!B16=""),"",'Monthly operating and hiring fo'!E9<'Pricing and operating assumptio'!B16))),0,IF(IF(IF(IFERROR('Model inputs'!B172=TRUE,FALSE),TRUE,IF(IFERROR('Model inputs'!B173=TRUE,FALSE),TRUE,IF(OR('Model inputs'!B172="",'Model inputs'!B173=""),"",OR('Model inputs'!B172,'Model inputs'!B173))))="",FALSE,IF(IFERROR('Model inputs'!B172=TRUE,FALSE),TRUE,IF(IFERROR('Model inputs'!B173=TRUE,FALSE),TRUE,IF(OR('Model inputs'!B172="",'Model inputs'!B173=""),"",OR('Model inputs'!B172,'Model inputs'!B173))))),1,0)) -> 0 | F27: =IF(IF(IF(ISERROR('Monthly operating and hiring fo'!F9<'Pricing and operating assumptio'!B16),'Monthly operating and hiring fo'!F9<'Pricing and operating assumptio'!B16,IF(OR('Monthly operating and hiring fo'!F9="",'Pricing and operating assumptio'!B16=""),"",'Monthly operating and hiring fo'!F9<'Pricing and operating assumptio'!B16))="",FALSE,IF(ISERROR('Monthly operating and hiring fo'!F9<'Pricing and operating assumptio'!B16),'Monthly operating and hiring fo'!F9<'Pricing and operating assumptio'!B16,IF(OR('Monthly operating and hiring fo'!F9="",'Pricing and operating assumptio'!B16=""),"",'Monthly operating and hiring fo'!F9<'Pricing and operating assumptio'!B16))),0,IF(IF(IF(IFERROR('Model inputs'!B174=TRUE,FALSE),TRUE,IF(IFERROR('Model inputs'!B175=TRUE,FALSE),TRUE,IF(OR('Model inputs'!B174="",'Model inputs'!B175=""),"",OR('Model inputs'!B174,'Model inputs'!B175))))="",FALSE,IF(IFERROR('Model inputs'!B174=TRUE,FALSE),TRUE,IF(IFERROR('Model inputs'!B175=TRUE,FALSE),TRUE,IF(OR('Model inputs'!B174="",'Model inputs'!B175=""),"",OR('Model inputs'!B174,'Model inputs'!B175))))),1,0)) -> 0 | G27: =IF(IF(IF(ISERROR('Monthly operating and hiring fo'!G9<'Pricing and operating assumptio'!B16),'Monthly operating and hiring fo'!G9<'Pricing and operating assumptio'!B16,IF(OR('Monthly operating and hiring fo'!G9="",'Pricing and operating assumptio'!B16=""),"",'Monthly operating and hiring fo'!G9<'Pricing and operating assumptio'!B16))="",FALSE,IF(ISERROR('Monthly operating and hiring fo'!G9<'Pricing and operating assumptio'!B16),'Monthly operating and hiring fo'!G9<'Pricing and operating assumptio'!B16,IF(OR('Monthly operating and hiring fo'!G9="",'Pricing and operating assumptio'!B16=""),"",'Monthly operating and hiring fo'!G9<'Pricing and operating assumptio'!B16))),0,IF(IF(IF(IFERROR('Model inputs'!B176=TRUE,FALSE),TRUE,IF(IFERROR('Model inputs'!B177=TRUE,FALSE),TRUE,IF(OR('Model inputs'!B176="",'Model inputs'!B177=""),"",OR('Model inputs'!B176,'Model inputs'!B177))))="",FALSE,IF(IFERROR('Model inputs'!B176=TRUE,FALSE),TRUE,IF(IFERROR('Model inputs'!B177=TRUE,FALSE),TRUE,IF(OR('Model inputs'!B176="",'Model inputs'!B177=""),"",OR('Model inputs'!B176,'Model inputs'!B177))))),1,0)) -> 0 | H27: =IF(IF(IF(ISERROR('Monthly operating and hiring fo'!H9<'Pricing and operating assumptio'!B16),'Monthly operating and hiring fo'!H9<'Pricing and operating assumptio'!B16,IF(OR('Monthly operating and hiring fo'!H9="",'Pricing and operating assumptio'!B16=""),"",'Monthly operating and hiring fo'!H9<'Pricing and operating assumptio'!B16))="",FALSE,IF(ISERROR('Monthly operating and hiring fo'!H9<'Pricing and operating assumptio'!B16),'Monthly operating and hiring fo'!H9<'Pricing and operating assumptio'!B16,IF(OR('Monthly operating and hiring fo'!H9="",'Pricing and operating assumptio'!B16=""),"",'Monthly operating and hiring fo'!H9<'Pricing and operating assumptio'!B16))),0,IF(IF(IF(IFERROR('Model inputs'!B178=TRUE,FALSE),TRUE,IF(IFERROR('Model inputs'!B179=TRUE,FALSE),TRUE,IF(OR('Model inputs'!B178="",'Model inputs'!B179=""),"",OR('Model inputs'!B178,'Model inputs'!B179))))="",FALSE,IF(IFERROR('Model inputs'!B178=TRUE,FALSE),TRUE,IF(IFERROR('Model inputs'!B179=TRUE,FALSE),TRUE,IF(OR('Model inputs'!B178="",'Model inputs'!B179=""),"",OR('Model inputs'!B178,'Model inputs'!B179))))),1,0)) -> 0 | I27: =IF(IF(IF(ISERROR('Monthly operating and hiring fo'!I9<'Pricing and operating assumptio'!B16),'Monthly operating and hiring fo'!I9<'Pricing and operating assumptio'!B16,IF(OR('Monthly operating and hiring fo'!I9="",'Pricing and operating assumptio'!B16=""),"",'Monthly operating and hiring fo'!I9<'Pricing and operating assumptio'!B16))="",FALSE,IF(ISERROR('Monthly operating and hiring fo'!I9<'Pricing and operating assumptio'!B16),'Monthly operating and hiring fo'!I9<'Pricing and operating assumptio'!B16,IF(OR('Monthly operating and hiring fo'!I9="",'Pricing and operating assumptio'!B16=""),"",'Monthly operating and hiring fo'!I9<'Pricing and operating assumptio'!B16))),0,IF(IF(IF(IFERROR('Model inputs'!B180=TRUE,FALSE),TRUE,IF(IFERROR('Model inputs'!B181=TRUE,FALSE),TRUE,IF(OR('Model inputs'!B180="",'Model inputs'!B181=""),"",OR('Model inputs'!B180,'Model inputs'!B181))))="",FALSE,IF(IFERROR('Model inputs'!B180=TRUE,FALSE),TRUE,IF(IFERROR('Model inputs'!B181=TRUE,FALSE),TRUE,IF(OR('Model inputs'!B180="",'Model inputs'!B181=""),"",OR('Model inputs'!B180,'Model inputs'!B181))))),1,0)) -> 0 | J27: =IF(IF(IF(ISERROR('Monthly operating and hiring fo'!J9<'Pricing and operating assumptio'!B16),'Monthly operating and hiring fo'!J9<'Pricing and operating assumptio'!B16,IF(OR('Monthly operating and hiring fo'!J9="",'Pricing and operating assumptio'!B16=""),"",'Monthly operating and hiring fo'!J9<'Pricing and operating assumptio'!B16))="",FALSE,IF(ISERROR('Monthly operating and hiring fo'!J9<'Pricing and operating assumptio'!B16),'Monthly operating and hiring fo'!J9<'Pricing and operating assumptio'!B16,IF(OR('Monthly operating and hiring fo'!J9="",'Pricing and operating assumptio'!B16=""),"",'Monthly operating and hiring fo'!J9<'Pricing and operating assumptio'!B16))),0,IF(IF(IF(IFERROR('Model inputs'!B182=TRUE,FALSE),TRUE,IF(IFERROR('Model inputs'!B183=TRUE,FALSE),TRUE,IF(OR('Model inputs'!B182="",'Model inputs'!B183=""),"",OR('Model inputs'!B182,'Model inputs'!B183))))="",FALSE,IF(IFERROR('Model inputs'!B182=TRUE,FALSE),TRUE,IF(IFERROR('Model inputs'!B183=TRUE,FALSE),TRUE,IF(OR('Model inputs'!B182="",'Model inputs'!B183=""),"",OR('Model inputs'!B182,'Model inputs'!B183))))),1,0)) -> 0 | K27: =IF(IF(IF(ISERROR('Monthly operating and hiring fo'!K9<'Pricing and operating assumptio'!B16),'Monthly operating and hiring fo'!K9<'Pricing and operating assumptio'!B16,IF(OR('Monthly operating and hiring fo'!K9="",'Pricing and operating assumptio'!B16=""),"",'Monthly operating and hiring fo'!K9<'Pricing and operating assumptio'!B16))="",FALSE,IF(ISERROR('Monthly operating and hiring fo'!K9<'Pricing and operating assumptio'!B16),'Monthly operating and hiring fo'!K9<'Pricing and operating assumptio'!B16,IF(OR('Monthly operating and hiring fo'!K9="",'Pricing and operating assumptio'!B16=""),"",'Monthly operating and hiring fo'!K9<'Pricing and operating assumptio'!B16))),0,IF(IF(IF(IFERROR('Model inputs'!B184=TRUE,FALSE),TRUE,IF(IFERROR('Model inputs'!B185=TRUE,FALSE),TRUE,IF(OR('Model inputs'!B184="",'Model inputs'!B185=""),"",OR('Model inputs'!B184,'Model inputs'!B185))))="",FALSE,IF(IFERROR('Model inputs'!B184=TRUE,FALSE),TRUE,IF(IFERROR('Model inputs'!B185=TRUE,FALSE),TRUE,IF(OR('Model inputs'!B184="",'Model inputs'!B185=""),"",OR('Model inputs'!B184,'Model inputs'!B185))))),1,0)) -> 0 | L27: =IF(IF(IF(ISERROR('Monthly operating and hiring fo'!L9<'Pricing and operating assumptio'!B16),'Monthly operating and hiring fo'!L9<'Pricing and operating assumptio'!B16,IF(OR('Monthly operating and hiring fo'!L9="",'Pricing and operating assumptio'!B16=""),"",'Monthly operating and hiring fo'!L9<'Pricing and operating assumptio'!B16))="",FALSE,IF(ISERROR('Monthly operating and hiring fo'!L9<'Pricing and operating assumptio'!B16),'Monthly operating and hiring fo'!L9<'Pricing and operating assumptio'!B16,IF(OR('Monthly operating and hiring fo'!L9="",'Pricing and operating assumptio'!B16=""),"",'Monthly operating and hiring fo'!L9<'Pricing and operating assumptio'!B16))),0,IF(IF(IF(IFERROR('Model inputs'!B186=TRUE,FALSE),TRUE,IF(IFERROR('Model inputs'!B187=TRUE,FALSE),TRUE,IF(OR('Model inputs'!B186="",'Model inputs'!B187=""),"",OR('Model inputs'!B186,'Model inputs'!B187))))="",FALSE,IF(IFERROR('Model inputs'!B186=TRUE,FALSE),TRUE,IF(IFERROR('Model inputs'!B187=TRUE,FALSE),TRUE,IF(OR('Model inputs'!B186="",'Model inputs'!B187=""),"",OR('Model inputs'!B186,'Model inputs'!B187))))),1,0)) -> 0 | M27: =IF(IF(IF(ISERROR('Monthly operating and hiring fo'!M9<'Pricing and operating assumptio'!B16),'Monthly operating and hiring fo'!M9<'Pricing and operating assumptio'!B16,IF(OR('Monthly operating and hiring fo'!M9="",'Pricing and operating assumptio'!B16=""),"",'Monthly operating and hiring fo'!M9<'Pricing and operating assumptio'!B16))="",FALSE,IF(ISERROR('Monthly operating and hiring fo'!M9<'Pricing and operating assumptio'!B16),'Monthly operating and hiring fo'!M9<'Pricing and operating assumptio'!B16,IF(OR('Monthly operating and hiring fo'!M9="",'Pricing and operating assumptio'!B16=""),"",'Monthly operating and hiring fo'!M9<'Pricing and operating assumptio'!B16))),0,IF(IF(IF(IFERROR('Model inputs'!B188=TRUE,FALSE),TRUE,IF(IFERROR('Model inputs'!B189=TRUE,FALSE),TRUE,IF(OR('Model inputs'!B188="",'Model inputs'!B189=""),"",OR('Model inputs'!B188,'Model inputs'!B189))))="",FALSE,IF(IFERROR('Model inputs'!B188=TRUE,FALSE),TRUE,IF(IFERROR('Model inputs'!B189=TRUE,FALSE),TRUE,IF(OR('Model inputs'!B188="",'Model inputs'!B189=""),"",OR('Model inputs'!B188,'Model inputs'!B189))))),1,0)) -> 0
A28: Engineer cost | B28: ='Monthly operating and hiring fo'!B27*'Pricing and operating assumptio'!B15 -> 0 | C28: ='Monthly operating and hiring fo'!C27*'Pricing and operating assumptio'!B15 -> 0 | D28: ='Monthly operating and hiring fo'!D27*'Pricing and operating assumptio'!B15 -> 0 | E28: ='Monthly operating and hiring fo'!E27*'Pricing and operating assumptio'!B15 -> 0 | F28: ='Monthly operating and hiring fo'!F27*'Pricing and operating assumptio'!B15 -> 0 | G28: ='Monthly operating and hiring fo'!G27*'Pricing and operating assumptio'!B15 -> 0 | H28: ='Monthly operating and hiring fo'!H27*'Pricing and operating assumptio'!B15 -> 0 | I28: ='Monthly operating and hiring fo'!I27*'Pricing and operating assumptio'!B15 -> 0 | J28: ='Monthly operating and hiring fo'!J27*'Pricing and operating assumptio'!B15 -> 0 | K28: ='Monthly operating and hiring fo'!K27*'Pricing and operating assumptio'!B15 -> 0 | L28: ='Monthly operating and hiring fo'!L27*'Pricing and operating assumptio'!B15 -> 0 | M28: ='Monthly operating and hiring fo'!M27*'Pricing and operating assumptio'!B15 -> 0
A29: Operating cash flow | B29: ='Monthly operating and hiring fo'!B23-'Monthly operating and hiring fo'!B28 -> -154.5 | C29: ='Monthly operating and hiring fo'!C23-'Monthly operating and hiring fo'!C28 -> 25 | D29: ='Monthly operating and hiring fo'!D23-'Monthly operating and hiring fo'!D28 -> 203 | E29: ='Monthly operating and hiring fo'!E23-'Monthly operating and hiring fo'!E28 -> 387 | F29: ='Monthly operating and hiring fo'!F23-'Monthly operating and hiring fo'!F28 -> 571 | G29: ='Monthly operating and hiring fo'!G23-'Monthly operating and hiring fo'!G28 -> 755 | H29: ='Monthly operating and hiring fo'!H23-'Monthly operating and hiring fo'!H28 -> -2693 | I29: ='Monthly operating and hiring fo'!I23-'Monthly operating and hiring fo'!I28 -> -2141 | ... M29: ='Monthly operating and hiring fo'!M23-'Monthly operating and hiring fo'!M28 -> 1355
A30: Cumulative operating cash | B30: =IF(IF(IF(ISERROR('Monthly operating and hiring fo'!B9=1),'Monthly operating and hiring fo'!B9=1,IF('Monthly operating and hiring fo'!B9="","",'Monthly operating and hiring fo'!B9=1))="",FALSE,IF(ISERROR('Monthly operating and hiring fo'!B9=1),'Monthly operating and hiring fo'!B9=1,IF('Monthly operating and hiring fo'!B9="","",'Monthly operating and hiring fo'!B9=1))),IF('Monthly operating and hiring fo'!B29="","",'Monthly operating and hiring fo'!B29),'Model inputs'!B15+'Monthly operating and hiring fo'!B29) -> -154.5 | C30: =IF(IF(IF(ISERROR('Monthly operating and hiring fo'!C9=1),'Monthly operating and hiring fo'!C9=1,IF('Monthly operating and hiring fo'!C9="","",'Monthly operating and hiring fo'!C9=1))="",FALSE,IF(ISERROR('Monthly operating and hiring fo'!C9=1),'Monthly operating and hiring fo'!C9=1,IF('Monthly operating and hiring fo'!C9="","",'Monthly operating and hiring fo'!C9=1))),IF('Monthly operating and hiring fo'!C29="","",'Monthly operating and hiring fo'!C29),'Monthly operating and hiring fo'!B30+'Monthly operating and hiring fo'!C29) -> -129.5 | D30: =IF(IF(IF(ISERROR('Monthly operating and hiring fo'!D9=1),'Monthly operating and hiring fo'!D9=1,IF('Monthly operating and hiring fo'!D9="","",'Monthly operating and hiring fo'!D9=1))="",FALSE,IF(ISERROR('Monthly operating and hiring fo'!D9=1),'Monthly operating and hiring fo'!D9=1,IF('Monthly operating and hiring fo'!D9="","",'Monthly operating and hiring fo'!D9=1))),IF('Monthly operating and hiring fo'!D29="","",'Monthly operating and hiring fo'!D29),'Monthly operating and hiring fo'!C30+'Monthly operating and hiring fo'!D29) -> 73.5 | E30: =IF(IF(IF(ISERROR('Monthly operating and hiring fo'!E9=1),'Monthly operating and hiring fo'!E9=1,IF('Monthly operating and hiring fo'!E9="","",'Monthly operating and hiring fo'!E9=1))="",FALSE,IF(ISERROR('Monthly operating and hiring fo'!E9=1),'Monthly operating and hiring fo'!E9=1,IF('Monthly operating and hiring fo'!E9="","",'Monthly operating and hiring fo'!E9=1))),IF('Monthly operating and hiring fo'!E29="","",'Monthly operating and hiring fo'!E29),'Monthly operating and hiring fo'!D30+'Monthly operating and hiring fo'!E29) -> 460.5 | F30: =IF(IF(IF(ISERROR('Monthly operating and hiring fo'!F9=1),'Monthly operating and hiring fo'!F9=1,IF('Monthly operating and hiring fo'!F9="","",'Monthly operating and hiring fo'!F9=1))="",FALSE,IF(ISERROR('Monthly operating and hiring fo'!F9=1),'Monthly operating and hiring fo'!F9=1,IF('Monthly operating and hiring fo'!F9="","",'Monthly operating and hiring fo'!F9=1))),IF('Monthly operating and hiring fo'!F29="","",'Monthly operating and hiring fo'!F29),'Monthly operating and hiring fo'!E30+'Monthly operating and hiring fo'!F29) -> 1031.5 | G30: =IF(IF(IF(ISERROR('Monthly operating and hiring fo'!G9=1),'Monthly operating and hiring fo'!G9=1,IF('Monthly operating and hiring fo'!G9="","",'Monthly operating and hiring fo'!G9=1))="",FALSE,IF(ISERROR('Monthly operating and hiring fo'!G9=1),'Monthly operating and hiring fo'!G9=1,IF('Monthly operating and hiring fo'!G9="","",'Monthly operating and hiring fo'!G9=1))),IF('Monthly operating and hiring fo'!G29="","",'Monthly operating and hiring fo'!G29),'Monthly operating and hiring fo'!F30+'Monthly operating and hiring fo'!G29) -> 1786.5 | H30: =IF(IF(IF(ISERROR('Monthly operating and hiring fo'!H9=1),'Monthly operating and hiring fo'!H9=1,IF('Monthly operating and hiring fo'!H9="","",'Monthly operating and hiring fo'!H9=1))="",FALSE,IF(ISERROR('Monthly operating and hiring fo'!H9=1),'Monthly operating and hiring fo'!H9=1,IF('Monthly operating and hiring fo'!H9="","",'Monthly operating and hiring fo'!H9=1))),IF('Monthly operating and hiring fo'!H29="","",'Monthly operating and hiring fo'!H29),'Monthly operating and hiring fo'!G30+'Monthly operating and hiring fo'!H29) -> -906.5 | I30: =IF(IF(IF(ISERROR('Monthly operating and hiring fo'!I9=1),'Monthly operating and hiring fo'!I9=1,IF('Monthly operating and hiring fo'!I9="","",'Monthly operating and hiring fo'!I9=1))="",FALSE,IF(ISERROR('Monthly operating and hiring fo'!I9=1),'Monthly operating and hiring fo'!I9=1,IF('Monthly operating and hiring fo'!I9="","",'Monthly operating and hiring fo'!I9=1))),IF('Monthly operating and hiring fo'!I29="","",'Monthly operating and hiring fo'!I29),'Monthly operating and hiring fo'!H30+'Monthly operating and hiring fo'!I29) -> -3047.5 | J30: =IF(IF(IF(ISERROR('Monthly operating and hiring fo'!J9=1),'Monthly operating and hiring fo'!J9=1,IF('Monthly operating and hiring fo'!J9="","",'Monthly operating and hiring fo'!J9=1))="",FALSE,IF(ISERROR('Monthly operating and hiring fo'!J9=1),'Monthly operating and hiring fo'!J9=1,IF('Monthly operating and hiring fo'!J9="","",'Monthly operating and hiring fo'!J9=1))),IF('Monthly operating and hiring fo'!J29="","",'Monthly operating and hiring fo'!J29),'Monthly operating and hiring fo'!I30+'Monthly operating and hiring fo'!J29) -> -4452.5 | ... M30: =IF(IF(IF(ISERROR('Monthly operating and hiring fo'!M9=1),'Monthly operating and hiring fo'!M9=1,IF('Monthly operating and hiring fo'!M9="","",'Monthly operating and hiring fo'!M9=1))="",FALSE,IF(ISERROR('Monthly operating and hiring fo'!M9=1),'Monthly operating and hiring fo'!M9=1,IF('Monthly operating and hiring fo'!M9="","",'Monthly operating and hiring fo'!M9=1))),IF('Monthly operating and hiring fo'!M29="","",'Monthly operating and hiring fo'!M29),'Monthly operating and hiring fo'!L30+'Monthly operating and hiring fo'!M29) -> -3147.5
A31: Minimum funding to date | B31: =IF(IF(IF(ISERROR('Monthly operating and hiring fo'!B9=1),'Monthly operating and hiring fo'!B9=1,IF('Monthly operating and hiring fo'!B9="","",'Monthly operating and hiring fo'!B9=1))="",FALSE,IF(ISERROR('Monthly operating and hiring fo'!B9=1),'Monthly operating and hiring fo'!B9=1,IF('Monthly operating and hiring fo'!B9="","",'Monthly operating and hiring fo'!B9=1))),MAX(0,-'Monthly operating and hiring fo'!B30),MAX(0,-'Monthly operating and hiring fo'!B30,'Model inputs'!B44)) -> 154.5 | C31: =IF(IF(IF(ISERROR('Monthly operating and hiring fo'!C9=1),'Monthly operating and hiring fo'!C9=1,IF('Monthly operating and hiring fo'!C9="","",'Monthly operating and hiring fo'!C9=1))="",FALSE,IF(ISERROR('Monthly operating and hiring fo'!C9=1),'Monthly operating and hiring fo'!C9=1,IF('Monthly operating and hiring fo'!C9="","",'Monthly operating and hiring fo'!C9=1))),MAX(0,-'Monthly operating and hiring fo'!C30),MAX(0,-'Monthly operating and hiring fo'!C30,'Monthly operating and hiring fo'!B31)) -> 154.5 | D31: =IF(IF(IF(ISERROR('Monthly operating and hiring fo'!D9=1),'Monthly operating and hiring fo'!D9=1,IF('Monthly operating and hiring fo'!D9="","",'Monthly operating and hiring fo'!D9=1))="",FALSE,IF(ISERROR('Monthly operating and hiring fo'!D9=1),'Monthly operating and hiring fo'!D9=1,IF('Monthly operating and hiring fo'!D9="","",'Monthly operating and hiring fo'!D9=1))),MAX(0,-'Monthly operating and hiring fo'!D30),MAX(0,-'Monthly operating and hiring fo'!D30,'Monthly operating and hiring fo'!C31)) -> 154.5 | E31: =IF(IF(IF(ISERROR('Monthly operating and hiring fo'!E9=1),'Monthly operating and hiring fo'!E9=1,IF('Monthly operating and hiring fo'!E9="","",'Monthly operating and hiring fo'!E9=1))="",FALSE,IF(ISERROR('Monthly operating and hiring fo'!E9=1),'Monthly operating and hiring fo'!E9=1,IF('Monthly operating and hiring fo'!E9="","",'Monthly operating and hiring fo'!E9=1))),MAX(0,-'Monthly operating and hiring fo'!E30),MAX(0,-'Monthly operating and hiring fo'!E30,'Monthly operating and hiring fo'!D31)) -> 154.5 | F31: =IF(IF(IF(ISERROR('Monthly operating and hiring fo'!F9=1),'Monthly operating and hiring fo'!F9=1,IF('Monthly operating and hiring fo'!F9="","",'Monthly operating and hiring fo'!F9=1))="",FALSE,IF(ISERROR('Monthly operating and hiring fo'!F9=1),'Monthly operating and hiring fo'!F9=1,IF('Monthly operating and hiring fo'!F9="","",'Monthly operating and hiring fo'!F9=1))),MAX(0,-'Monthly operating and hiring fo'!F30),MAX(0,-'Monthly operating and hiring fo'!F30,'Monthly operating and hiring fo'!E31)) -> 154.5 | G31: =IF(IF(IF(ISERROR('Monthly operating and hiring fo'!G9=1),'Monthly operating and hiring fo'!G9=1,IF('Monthly operating and hiring fo'!G9="","",'Monthly operating and hiring fo'!G9=1))="",FALSE,IF(ISERROR('Monthly operating and hiring fo'!G9=1),'Monthly operating and hiring fo'!G9=1,IF('Monthly operating and hiring fo'!G9="","",'Monthly operating and hiring fo'!G9=1))),MAX(0,-'Monthly operating and hiring fo'!G30),MAX(0,-'Monthly operating and hiring fo'!G30,'Monthly operating and hiring fo'!F31)) -> 154.5 | H31: =IF(IF(IF(ISERROR('Monthly operating and hiring fo'!H9=1),'Monthly operating and hiring fo'!H9=1,IF('Monthly operating and hiring fo'!H9="","",'Monthly operating and hiring fo'!H9=1))="",FALSE,IF(ISERROR('Monthly operating and hiring fo'!H9=1),'Monthly operating and hiring fo'!H9=1,IF('Monthly operating and hiring fo'!H9="","",'Monthly operating and hiring fo'!H9=1))),MAX(0,-'Monthly operating and hiring fo'!H30),MAX(0,-'Monthly operating and hiring fo'!H30,'Monthly operating and hiring fo'!G31)) -> 906.5 | I31: =IF(IF(IF(ISERROR('Monthly operating and hiring fo'!I9=1),'Monthly operating and hiring fo'!I9=1,IF('Monthly operating and hiring fo'!I9="","",'Monthly operating and hiring fo'!I9=1))="",FALSE,IF(ISERROR('Monthly operating and hiring fo'!I9=1),'Monthly operating and hiring fo'!I9=1,IF('Monthly operating and hiring fo'!I9="","",'Monthly operating and hiring fo'!I9=1))),MAX(0,-'Monthly operating and hiring fo'!I30),MAX(0,-'Monthly operating and hiring fo'!I30,'Monthly operating and hiring fo'!H31)) -> 3047.5 | J31: =IF(IF(IF(ISERROR('Monthly operating and hiring fo'!J9=1),'Monthly operating and hiring fo'!J9=1,IF('Monthly operating and hiring fo'!J9="","",'Monthly operating and hiring fo'!J9=1))="",FALSE,IF(ISERROR('Monthly operating and hiring fo'!J9=1),'Monthly operating and hiring fo'!J9=1,IF('Monthly operating and hiring fo'!J9="","",'Monthly operating and hiring fo'!J9=1))),MAX(0,-'Monthly operating and hiring fo'!J30),MAX(0,-'Monthly operating and hiring fo'!J30,'Monthly operating and hiring fo'!I31)) -> 4452.5 | ... M31: =IF(IF(IF(ISERROR('Monthly operating and hiring fo'!M9=1),'Monthly operating and hiring fo'!M9=1,IF('Monthly operating and hiring fo'!M9="","",'Monthly operating and hiring fo'!M9=1))="",FALSE,IF(ISERROR('Monthly operating and hiring fo'!M9=1),'Monthly operating and hiring fo'!M9=1,IF('Monthly operating and hiring fo'!M9="","",'Monthly operating and hiring fo'!M9=1))),MAX(0,-'Monthly operating and hiring fo'!M30),MAX(0,-'Monthly operating and hiring fo'!M30,'Monthly operating and hiring fo'!L31)) -> 4937.5
